2022-02-19 18:32:41,519 - apscheduler.scheduler - INFO - Scheduler started
2022-02-19 18:34:51,822 - __main__ - INFO - Received request to join challenge.
2022-02-19 18:34:51,823 - __main__ - INFO - Failed to add 190779022 to database
2022-02-19 18:36:06,868 - telegram.ext.updater - INFO - Received signal 2 (SIGINT), stopping...
2022-02-19 18:36:06,868 - apscheduler.scheduler - INFO - Scheduler has been shut down
2022-02-19 18:36:14,564 - telegram.ext.updater - WARNING - Exiting immediately!
2022-02-19 18:36:15,619 - apscheduler.scheduler - INFO - Scheduler started
2022-02-19 18:36:18,843 - telegram.ext.updater - INFO - Received signal 2 (SIGINT), stopping...
2022-02-19 18:36:18,843 - apscheduler.scheduler - INFO - Scheduler has been shut down
2022-02-19 18:36:19,050 - telegram.ext.updater - WARNING - Exiting immediately!
2022-02-19 18:36:22,666 - apscheduler.scheduler - INFO - Scheduler started
2022-02-19 18:36:34,325 - __main__ - INFO - Received request to join challenge.
2022-02-19 18:36:34,326 - __main__ - INFO - Failed to add 190779022 to database
2022-02-19 23:16:55,321 - telegram.ext.updater - ERROR - Error while getting Updates: urllib3 HTTPError ('Connection aborted.', ConnectionResetError(10054, 'An existing connection was forcibly closed by the remote host', None, 10054, None))
2022-02-19 23:16:59,581 - telegram.ext.updater - INFO - Received signal 2 (SIGINT), stopping...
2022-02-19 23:16:59,581 - apscheduler.scheduler - INFO - Scheduler has been shut down
2022-02-19 23:16:59,723 - telegram.ext.updater - WARNING - Exiting immediately!
2022-02-19 23:17:01,625 - apscheduler.scheduler - INFO - Scheduler started
2022-02-20 10:09:10,587 - telegram.vendor.ptb_urllib3.urllib3.connectionpool - WARNING - Retrying (Retry(total=2, connect=None, read=None, redirect=None)) after connection broken by 'NewConnectionError('<telegram.vendor.ptb_urllib3.urllib3.connection.VerifiedHTTPSConnection object at 0x0000012FD0373A30>: Failed to establish a new connection: [Errno 11001] getaddrinfo failed')': /bot5170999625:AAHC47FziHEpapGE5XoU4CmrtXDXMgy5V7c/getUpdates
2022-02-20 10:09:10,587 - telegram.vendor.ptb_urllib3.urllib3.connectionpool - WARNING - Retrying (Retry(total=1, connect=None, read=None, redirect=None)) after connection broken by 'NewConnectionError('<telegram.vendor.ptb_urllib3.urllib3.connection.VerifiedHTTPSConnection object at 0x0000012FD037E370>: Failed to establish a new connection: [Errno 11001] getaddrinfo failed')': /bot5170999625:AAHC47FziHEpapGE5XoU4CmrtXDXMgy5V7c/getUpdates
2022-02-20 10:09:10,587 - telegram.vendor.ptb_urllib3.urllib3.connectionpool - WARNING - Retrying (Retry(total=0, connect=None, read=None, redirect=None)) after connection broken by 'NewConnectionError('<telegram.vendor.ptb_urllib3.urllib3.connection.VerifiedHTTPSConnection object at 0x0000012FD037E460>: Failed to establish a new connection: [Errno 11001] getaddrinfo failed')': /bot5170999625:AAHC47FziHEpapGE5XoU4CmrtXDXMgy5V7c/getUpdates
2022-02-20 10:09:10,587 - telegram.ext.updater - ERROR - Error while getting Updates: urllib3 HTTPError HTTPSConnectionPool(host='api.telegram.org', port=443): Max retries exceeded with url: /bot5170999625:AAHC47FziHEpapGE5XoU4CmrtXDXMgy5V7c/getUpdates (Caused by NewConnectionError('<telegram.vendor.ptb_urllib3.urllib3.connection.VerifiedHTTPSConnection object at 0x0000012FD037E520>: Failed to establish a new connection: [Errno 11001] getaddrinfo failed'))
2022-02-20 10:09:11,591 - telegram.vendor.ptb_urllib3.urllib3.connectionpool - WARNING - Retrying (Retry(total=2, connect=None, read=None, redirect=None)) after connection broken by 'NewConnectionError('<telegram.vendor.ptb_urllib3.urllib3.connection.VerifiedHTTPSConnection object at 0x0000012FD037E220>: Failed to establish a new connection: [Errno 11001] getaddrinfo failed')': /bot5170999625:AAHC47FziHEpapGE5XoU4CmrtXDXMgy5V7c/getUpdates
2022-02-20 10:09:11,592 - telegram.vendor.ptb_urllib3.urllib3.connectionpool - WARNING - Retrying (Retry(total=1, connect=None, read=None, redirect=None)) after connection broken by 'NewConnectionError('<telegram.vendor.ptb_urllib3.urllib3.connection.VerifiedHTTPSConnection object at 0x0000012FD037E700>: Failed to establish a new connection: [Errno 11001] getaddrinfo failed')': /bot5170999625:AAHC47FziHEpapGE5XoU4CmrtXDXMgy5V7c/getUpdates
2022-02-20 10:09:11,592 - telegram.vendor.ptb_urllib3.urllib3.connectionpool - WARNING - Retrying (Retry(total=0, connect=None, read=None, redirect=None)) after connection broken by 'NewConnectionError('<telegram.vendor.ptb_urllib3.urllib3.connection.VerifiedHTTPSConnection object at 0x0000012FD037E850>: Failed to establish a new connection: [Errno 11001] getaddrinfo failed')': /bot5170999625:AAHC47FziHEpapGE5XoU4CmrtXDXMgy5V7c/getUpdates
2022-02-20 10:09:11,592 - telegram.ext.updater - ERROR - Error while getting Updates: urllib3 HTTPError HTTPSConnectionPool(host='api.telegram.org', port=443): Max retries exceeded with url: /bot5170999625:AAHC47FziHEpapGE5XoU4CmrtXDXMgy5V7c/getUpdates (Caused by NewConnectionError('<telegram.vendor.ptb_urllib3.urllib3.connection.VerifiedHTTPSConnection object at 0x0000012FD037E9A0>: Failed to establish a new connection: [Errno 11001] getaddrinfo failed'))
2022-02-20 10:09:13,094 - telegram.vendor.ptb_urllib3.urllib3.connectionpool - WARNING - Retrying (Retry(total=2, connect=None, read=None, redirect=None)) after connection broken by 'NewConnectionError('<telegram.vendor.ptb_urllib3.urllib3.connection.VerifiedHTTPSConnection object at 0x0000012FD037E5E0>: Failed to establish a new connection: [Errno 11001] getaddrinfo failed')': /bot5170999625:AAHC47FziHEpapGE5XoU4CmrtXDXMgy5V7c/getUpdates
2022-02-20 10:09:13,094 - telegram.vendor.ptb_urllib3.urllib3.connectionpool - WARNING - Retrying (Retry(total=1, connect=None, read=None, redirect=None)) after connection broken by 'NewConnectionError('<telegram.vendor.ptb_urllib3.urllib3.connection.VerifiedHTTPSConnection object at 0x0000012FD037EB80>: Failed to establish a new connection: [Errno 11001] getaddrinfo failed')': /bot5170999625:AAHC47FziHEpapGE5XoU4CmrtXDXMgy5V7c/getUpdates
2022-02-20 10:09:13,095 - telegram.vendor.ptb_urllib3.urllib3.connectionpool - WARNING - Retrying (Retry(total=0, connect=None, read=None, redirect=None)) after connection broken by 'NewConnectionError('<telegram.vendor.ptb_urllib3.urllib3.connection.VerifiedHTTPSConnection object at 0x0000012FD037ECD0>: Failed to establish a new connection: [Errno 11001] getaddrinfo failed')': /bot5170999625:AAHC47FziHEpapGE5XoU4CmrtXDXMgy5V7c/getUpdates
2022-02-20 10:09:13,095 - telegram.ext.updater - ERROR - Error while getting Updates: urllib3 HTTPError HTTPSConnectionPool(host='api.telegram.org', port=443): Max retries exceeded with url: /bot5170999625:AAHC47FziHEpapGE5XoU4CmrtXDXMgy5V7c/getUpdates (Caused by NewConnectionError('<telegram.vendor.ptb_urllib3.urllib3.connection.VerifiedHTTPSConnection object at 0x0000012FD037EE20>: Failed to establish a new connection: [Errno 11001] getaddrinfo failed'))
